Workbook

Sheet raw
A1: region | B1: comm_sports | C1: comm_non_sports | D1: comm_sports_inclusive | E1: comm_non_sports_inclusive | F1: comm_family_learn | G1: comm_neglang_people | H1: comm_neglang_media | I1: comm_kept | J1: edu_daycare_law | K1: edu_daycare_inclusive | L1: edu_school_adapt | M1: edu_school_inclusive | N1: edu_law_freepostsecondary | O1: edu_daycare_access | P1: edu_school_enroll | Q1: edu_inclusion | R1: edu_inclusion2 | S1: edu_curriculum_adapted | T1: edu_teacher_training | U1: health_prenatal | V1: health_nipt | W1: health_nips_paid | X1: health_prenatal_paid | Y1: health_terminate | Z1: health_prenatal_info | AA1: health_guidelines | AB1: clinic_children | AC1: clinic_adults | AD1: health_exp | AE1: healthy_qual | AF1: health_events_plan | AG1: health_speech | AH1: health_heart | AI1: health_hearing_test | AJ1: health_hearing_treat | AK1: health_mental | AL1: health_afford | AM1: health_birthcontrol | AN1: indep_transition | AO1: indep_transport | AP1: indep_edu_relationships | AQ1: indep_employer_accom | AR1: indep_govt_fin | AS1: indep_volunteer | AT1: indep_work_paid | AU1: indep_work_minwage | AV1: indep_work_20hr | AW1: indep_work_inclusive | AX1: indep_work_benefits | AY1: indep_livingexp | AZ1: indep_exclude | BA1: policy_edu | BB1: policy_vote | BC1: policy_nondiscrimination | BD1: policy_marry | BE1: policy_abuse_invest | BF1: policy_sterilization | BG1: policy_abandonunder | BH1: policy_abandonover | BI1: policy_abuse | BJ1: policy_openinput | BK1: comm_electricity | BL1: comm_sanitation | BM1: policy_influence
A2: Peru | B2: 2 | C2: 2 | D2: 2 | E2: 2 | F2: 4 | G2: 3 | H2: 2 | I2: 3 | J2: 2 | K2: 2 | L2: 2 | M2: 2 | N2: 2 | O2: 2 | P2: 2 | Q2: 2 | R2: 2 | S2: 1 | T2: 2 | U2: 2 | V2: 2 | W2: 2 | X2: 2 | Y2: 2 | Z2: 1 | AA2: 1 | AB2: 1 | AC2: 1 | AD2: 2 | AE2: 1 | AF2: 1 | AG2: 3 | AH2: 3 | AI2: 2 | AJ2: 2 | AK2: 1 | AL2: 2 | AM2: 1 | AN2: 1 | AO2: 1 | AP2: 1 | AQ2: 2 | AR2: 2 | AS2: 1 | AT2: 1 | AU2: 1 | AV2: 1 | AW2: 1 | AX2: 2 | AY2: 1 | AZ2: 4 | BA2: 3 | BB2: 3 | BC2: 1 | BD2: 1 | BE2: 1 | BF2: 1 | BG2: 0 | BH2: 0 | BI2: 2 | BJ2: 2 | BK2: 2 | BL2: 2 | BM2: 4
A3: Costa Rica | B3: 2 | C3: 2 | D3: 2 | E3: 2 | F3: 4 | G3: 2 | H3: 1 | I3: 4 | J3: 2 | K3: 2 | L3: 2 | M3: 2 | N3: 2 | O3: 3 | P3: 3 | Q3: 3 | R3: 2 | S3: 3 | T3: 3 | U3: 2 | V3: 2 | W3: 3 | X3: 3 | Y3: 1 | Z3: 2 | AA3: 2 | AB3: 2 | AC3: 1 | AD3: 1 | AE3: 1 | AF3: 2 | AG3: 4 | AH3: 4 | AI3: 3 | AJ3: 3 | AK3: 3 | AL3: 4 | AM3: 3 | AN3: 2 | AO3: 0 | AP3: 1 | AQ3: 2 | AR3: 2 | AS3: 2 | AT3: 3 | AU3: 2 | AV3: 2 | AW3: 3 | AX3: 3 | AY3: 1 | AZ3: 2 | BA3: 3 | BB3: 3 | BC3: 3 | BD3: 2 | BE3: 3 | BF3: 3 | BG3: 1 | BH3: 1 | BI3: 0 | BJ3: 2 | BK3: 2 | BL3: 2 | BM3: 3
A4: Costa Rica | B4: 2 | C4: 1 | D4: 2 | E4: 2 | F4: 4 | G4: 3 | H4: 2 | I4: 4 | J4: 2 | K4: 2 | L4: 2 | M4: 2 | N4: 1 | O4: 2 | P4: 2 | Q4: 2 | R4: 1 | S4: 2 | T4: 2 | U4: 2 | V4: 2 | W4: 1 | X4: 1 | Y4: 1 | Z4: 2 | AA4: 2 | AB4: 2 | AC4: 2 | AD4: 2 | AE4: 2 | AF4: 2 | AG4: 2 | AH4: 4 | AI4: 4 | AJ4: 2 | AK4: 2 | AL4: 4 | AM4: 1 | AN4: 1 | AO4: 1 | AP4: 1 | AQ4: 2 | AR4: 1 | AS4: 1 | AT4: 2 | AU4: 2 | AV4: 3 | AW4: 3 | AX4: 2 | AY4: 1 | AZ4: 3 | BA4: 3 | BB4: 3 | BC4: 3 | BD4: 1 | BE4: 3 | BF4: 3 | BG4: 1 | BH4: 1 | BI4: 2 | BJ4: 0 | BK4: 2 | BL4: 2 | BM4: 4
A5: Chile | B5: 2 | C5: 2 | D5: 0 | E5: 0 | F5: 2 | G5: 1 | H5: 1 | I5: 1 | J5: 1 | K5: 2 | L5: 1 | M5: 2 | N5: 1 | O5: 4 | P5: 3 | Q5: 4 | R5: 3 | S5: 2 | T5: 1 | U5: 1 | AA5: 1 | AB5: 1 | AC5: 1 | AD5: 2 | AE5: 2 | AF5: 0 | AG5: 4 | AH5: 4 | AI5: 4 | AJ5: 3 | AK5: 2 | AL5: 2 | AM5: 1 | AN5: 1 | AO5: 1 | AP5: 1 | AQ5: 2 | AR5: 3 | AS5: 2 | AT5: 3 | AU5: 3 | AV5: 2 | AW5: 3 | AX5: 4 | AY5: 1 | AZ5: 3 | BA5: 1 | BB5: 3 | BC5: 0 | BD5: 1 | BE5: 0 | BF5: 0 | BG5: 1 | BH5: 1 | BI5: 0 | BJ5: 2 | BK5: 2 | BL5: 2 | BM5: 3
A6: Zimbabwe | B6: 0 | C6: 0 | D6: 0 | E6: 0 | F6: 2 | G6: 3 | H6: 4 | I6: 1 | J6: 2 | K6: 2 | L6: 0 | M6: 2 | N6: 1 | O6: 1 | P6: 1 | Q6: 1 | R6: 1 | S6: 1 | T6: 1 | U6: 0 | AA6: 1 | AB6: 1 | AC6: 1 | AD6: 2 | AE6: 2 | AF6: 1 | AG6: 1 | AH6: 1 | AI6: 1 | AJ6: 1 | AK6: 1 | AL6: 1 | AM6: 0 | AN6: 1 | AO6: 1 | AP6: 1 | AQ6: 2 | AR6: 1 | AS6: 1 | AT6: 1 | AU6: 1 | AV6: 0 | AW6: 0 | AX6: 0 | AY6: 1 | AZ6: 4 | BA6: 2 | BB6: 3 | BC6: 3 | BD6: 0 | BE6: 2 | BF6: 1 | BG6: 1 | BH6: 0 | BI6: 2 | BJ6: 2 | BK6: 2 | BL6: 2 | BM6: 4
A7: Spain | B7: 2 | C7: 2 | D7: 2 | E7: 2 | F7: 4 | G7: 3 | H7: 2 | I7: 1 | J7: 2 | K7: 2 | L7: 2 | M7: 2 | N7: 2 | O7: 4 | P7: 4 | Q7: 4 | R7: 2 | S7: 4 | T7: 4 | U7: 2 | V7: 2 | W7: 4 | X7: 4 | Y7: 3 | Z7: 1 | AA7: 2 | AB7: 2 | AC7: 2 | AD7: 2 | AE7: 2 | AF7: 2 | AG7: 4 | AH7: 4 | AI7: 4 | AJ7: 4 | AK7: 4 | AL7: 4 | AM7: 4 | AN7: 2 | AO7: 2 | AP7: 2 | AQ7: 2 | AR7: 3 | AS7: 2 | AT7: 2 | AU7: 3 | AV7: 2 | AW7: 2 | AX7: 2 | AY7: 1 | AZ7: 3 | BA7: 3 | BB7: 3 | BC7: 3 | BD7: 1 | BE7: 3 | BF7: 1 | BG7: 2 | BH7: 2 | BI7: 2 | BJ7: 2 | BK7: 2 | BL7: 1 | BM7: 2
A8: Guatemala | B8: 2 | C8: 2 | D8: 2 | E8: 2 | F8: 2 | G8: 2 | H8: 3 | I8: 4 | J8: 1 | K8: 2 | L8: 2 | M8: 2 | N8: 1 | O8: 1 | P8: 1 | Q8: 1 | R8: 1 | S8: 1 | T8: 1 | U8: 2 | V8: 2 | W8: 1 | X8: 1 | Y8: 1 | Z8: 1 | AA8: 1 | AB8: 1 | AC8: 1 | AD8: 1 | AE8: 1 | AF8: 1 | AG8: 2 | AH8: 4 | AI8: 2 | AJ8: 2 | AK8: 1 | AL8: 3 | AM8: 1 | AN8: 1 | AO8: 1 | AP8: 1 | AQ8: 1 | AR8: 1 | AS8: 1 | AT8: 1 | AU8: 2 | AV8: 0 | AW8: 3 | AX8: 2 | AY8: 1 | AZ8: 3 | BA8: 3 | BB8: 3 | BC8: 3 | BD8: 1 | BE8: 1 | BF8: 1 | BG8: 0 | BH8: 0 | BI8: 0 | BJ8: 1 | BK8: 2 | BL8: 2 | BM8: 2
A9: Colombia | B9: 2 | C9: 1 | D9: 1 | E9: 2 | F9: 2 | G9: 3 | H9: 2 | I9: 1 | J9: 2 | K9: 2 | L9: 2 | M9: 2 | N9: 2 | O9: 2 | P9: 2 | Q9: 2 | R9: 2 | S9: 1 | T9: 3 | U9: 2 | V9: 1 | X9: 1 | Y9: 4 | Z9: 1 | AA9: 1 | AB9: 1 | AC9: 1 | AD9: 1 | AE9: 1 | AF9: 2 | AG9: 4 | AH9: 2 | AI9: 4 | AJ9: 4 | AK9: 4 | AL9: 4 | AM9: 4 | AN9: 1 | AO9: 2 | AP9: 1 | AQ9: 2 | AR9: 2 | AS9: 2 | AT9: 2 | AU9: 2 | AV9: 2 | AW9: 3 | AX9: 3 | AY9: 1 | AZ9: 3 | BA9: 3 | BB9: 3 | BC9: 3 | BD9: 1 | BE9: 3 | BF9: 3 | BG9: 1 | BH9: 1 | BI9: 2 | BJ9: 2 | BK9: 2 | BL9: 2 | BM9: 4
A10: Colombia | B10: 2 | C10: 2 | D10: 2 | E10: 2 | F10: 4 | G10: 2 | H10: 1 | I10: 2 | J10: 2 | K10: 2 | L10: 2 | M10: 2 | N10: 2 | O10: 3 | P10: 3 | Q10: 3 | R10: 2 | S10: 3 | T10: 3 | U10: 2 | V10: 2 | W10: 3 | X10: 1 | Y10: 3 | Z10: 2 | AA10: 2 | AB10: 1 | AC10: 1 | AD10: 1 | AE10: 1 | AF10: 2 | AG10: 4 | AH10: 4 | AI10: 4 | AJ10: 4 | AK10: 2 | AL10: 4 | AM10: 1 | AN10: 1 | AO10: 1 | AP10: 2 | AQ10: 2 | AR10: 2 | AS10: 2 | AT10: 1 | AU10: 1 | AV10: 2 | AW10: 2 | AX10: 1 | AY10: 1 | AZ10: 3 | BA10: 3 | BB10: 3 | BC10: 3 | BD10: 1 | BE10: 2 | BF10: 3 | BG10: 1 | BH10: 1 | BI10: 2 | BJ10: 2 | BK10: 2 | BL10: 2 | BM10: 4
A11: Spain | B11: 2 | C11: 1 | D11: 2 | E11: 2 | F11: 4 | G11: 1 | H11: 1 | I11: 4 | J11: 2 | K11: 2 | L11: 2 | M11: 2 | N11: 2 | O11: 4 | P11: 4 | Q11: 3 | R11: 2 | S11: 3 | T11: 1 | U11: 2 | V11: 2 | W11: 4 | X11: 4 | Y11: 4 | Z11: 2 | AA11: 2 | AB11: 2 | AC11: 2 | AD11: 1 | AE11: 1 | AF11: 1 | AG11: 4 | AH11: 4 | AI11: 4 | AJ11: 4 | AK11: 3 | AL11: 4 | AM11: 4 | AN11: 2 | AO11: 2 | AP11: 1 | AQ11: 2 | AR11: 4 | AS11: 1 | AT11: 2 | AU11: 4 | AV11: 3 | AW11: 3 | AX11: 4 | AY11: 1 | AZ11: 2 | BA11: 3 | BB11: 3 | BC11: 3 | BD11: 1 | BE11: 3 | BF11: 3 | BG11: 1 | BH11: 1 | BI11: 2 | BJ11: 2 | BK11: 2 | BL11: 2 | BM11: 3
A12: Netherlands | B12: 2 | C12: 2 | D12: 2 | E12: 2 | F12: 4 | G12: 2 | H12: 2 | I12: 4 | J12: 1 | K12: 2 | L12: 1 | M12: 2 | N12: 1 | O12: 4 | P12: 4 | Q12: 3 | R12: 1 | S12: 4 | T12: 3 | U12: 2 | V12: 2 | W12: 4 | X12: 4 | Y12: 2 | Z12: 3 | AA12: 2 | AB12: 2 | AC12: 2 | AD12: 1 | AE12: 1 | AF12: 0 | AG12: 4 | AH12: 4 | AI12: 4 | AJ12: 4 | AK12: 4 | AL12: 4 | AM12: 4 | AN12: 2 | AO12: 1 | AP12: 2 | AQ12: 1 | AR12: 4 | AS12: 3 | AT12: 2 | AU12: 0 | AV12: 2 | AW12: 3 | AX12: 4 | AY12: 4 | AZ12: 2 | BA12: 3 | BB12: 3 | BC12: 3 | BD12: 1 | BE12: 3 | BF12: 3 | BG12: 1 | BH12: 1 | BI12: 0 | BJ12: 2 | BK12: 2 | BL12: 2 | BM12: 3
A13: Colombia | B13: 2 | C13: 2 | D13: 1 | E13: 2 | F13: 3 | G13: 3 | H13: 3 | I13: 3 | J13: 2 | K13: 2 | L13: 2 | M13: 2 | N13: 1 | O13: 3 | P13: 2 | Q13: 2 | R13: 2 | S13: 2 | T13: 2 | U13: 2 | V13: 2 | W13: 1 | X13: 1 | Y13: 4 | Z13: 2 | AA13: 1 | AB13: 1 | AC13: 1 | AD13: 2 | AE13: 2 | AF13: 0 | AG13: 2 | AH13: 3 | AI13: 2 | AJ13: 2 | AK13: 2 | AL13: 2 | AM13: 2 | AN13: 1 | AO13: 1 | AP13: 1 | AQ13: 1 | AR13: 1 | AS13: 1 | AT13: 2 | AU13: 3 | AV13: 2 | AW13: 4 | AX13: 2 | AY13: 1 | AZ13: 3 | BA13: 3 | BB13: 3 | BC13: 3 | BD13: 1 | BE13: 3 | BF13: 3 | BG13: 2 | BH13: 2 | BI13: 2 | BJ13: 2 | BK13: 2 | BL13: 2 | BM13: 2
A14: Iran | B14: 1 | C14: 1 | D14: 1 | E14: 1 | F14: 2 | G14: 4 | H14: 1 | I14: 4 | J14: 2 | K14: 2 | L14: 1 | M14: 1 | N14: 1 | O14: 1 | P14: 2 | Q14: 1 | R14: 1 | S14: 2 | T14: 1 | U14: 1 | AA14: 1 | AB14: 1 | AC14: 1 | AD14: 2 | AE14: 2 | AF14: 1 | AG14: 1 | AH14: 2 | AI14: 2 | AJ14: 2 | AK14: 2 | AL14: 1 | AM14: 1 | AN14: 1 | AO14: 1 | AP14: 1 | AQ14: 1 | AR14: 2 | AS14: 1 | AT14: 1 | AU14: 1 | AV14: 1 | AW14: 0 | AX14: 0 | AY14: 1 | AZ14: 1 | BA14: 1 | BB14: 1 | BC14: 1 | BD14: 1 | BE14: 1 | BF14: 1 | BG14: 2 | BH14: 0 | BI14: 1 | BJ14: 1 | BK14: 3 | BL14: 3 | BM14: 0
A15: Botswana | B15: 1 | C15: 1 | D15: 1 | E15: 1 | F15: 2 | G15: 2 | H15: 1 | I15: 3 | J15: 2 | K15: 2 | L15: 2 | M15: 0 | N15: 2 | O15: 2 | P15: 2 | Q15: 0 | R15: 0 | S15: 4 | T15: 3 | U15: 2 | V15: 0 | X15: 0 | Y15: 0 | Z15: 1 | AA15: 1 | AB15: 1 | AC15: 1 | AD15: 1 | AE15: 2 | AF15: 1 | AG15: 1 | AH15: 4 | AI15: 1 | AJ15: 2 | AK15: 1 | AL15: 4 | AM15: 2 | AN15: 1 | AO15: 1 | AP15: 1 | AQ15: 2 | AR15: 2 | AS15: 1 | AT15: 2 | AU15: 2 | AV15: 0 | AW15: 4 | AX15: 0 | AY15: 1 | AZ15: 4 | BA15: 2 | BB15: 3 | BC15: 3 | BD15: 0 | BE15: 1 | BF15: 1 | BG15: 1 | BH15: 1 | BI15: 0 | BJ15: 2 | BK15: 2 | BL15: 2 | BM15: 3
A16: China | B16: 2 | C16: 2 | D16: 0 | E16: 2 | F16: 3 | G16: 3 | H16: 1 | I16: 3 | J16: 2 | K16: 2 | L16: 1 | M16: 1 | N16: 2 | O16: 0 | P16: 4 | Q16: 2 | R16: 2 | S16: 1 | T16: 2 | U16: 2 | V16: 0 | X16: 2 | Y16: 2 | Z16: 1 | AA16: 1 | AB16: 1 | AC16: 1 | AD16: 2 | AE16: 2 | AF16: 0 | AG16: 4 | AH16: 4 | AI16: 4 | AJ16: 4 | AK16: 4 | AL16: 1 | AM16: 1 | AN16: 2 | AO16: 1 | AP16: 1 | AQ16: 1 | AR16: 4 | AS16: 1 | AT16: 2 | AU16: 1 | AV16: 1 | AW16: 2 | AX16: 1 | AY16: 1 | AZ16: 2 | BA16: 3 | BB16: 3 | BC16: 3 | BD16: 1 | BE16: 0 | BF16: 0 | BG16: 2 | BH16: 1 | BI16: 2 | BJ16: 0 | BK16: 3 | BL16: 2 | BM16: 2
A17: Peru | B17: 2 | C17: 2 | D17: 1 | E17: 1 | F17: 3 | G17: 2 | H17: 2 | I17: 4 | J17: 2 | K17: 2 | L17: 2 | M17: 2 | N17: 1 | O17: 2 | P17: 2 | Q17: 2 | R17: 2 | S17: 2 | T17: 2 | U17: 2 | X17: 1 | Y17: 1 | Z17: 1 | AA17: 1 | AB17: 2 | AC17: 1 | AD17: 2 | AE17: 2 | AF17: 2 | AG17: 2 | AH17: 2 | AI17: 1 | AJ17: 1 | AK17: 2 | AL17: 3 | AM17: 1 | AN17: 1 | AO17: 1 | AP17: 1 | AQ17: 1 | AR17: 1 | AS17: 2 | AT17: 2 | AU17: 1 | AV17: 1 | AW17: 2 | AX17: 2 | AY17: 1 | AZ17: 3 | BA17: 3 | BB17: 3 | BC17: 3 | BD17: 1 | BE17: 1 | BF17: 1 | BG17: 1 | BH17: 1 | BI17: 2 | BJ17: 2 | BK17: 1 | BL17: 1 | BM17: 2
A18: Georgia | B18: 2 | C18: 2 | D18: 2 | E18: 2 | F18: 3 | G18: 2 | H18: 1 | I18: 4 | J18: 2 | K18: 2 | L18: 2 | M18: 2 | N18: 1 | O18: 2 | P18: 3 | Q18: 3 | R18: 2 | S18: 2 | T18: 2 | U18: 2 | X18: 3 | Y18: 3 | Z18: 1 | AA18: 1 | AB18: 1 | AC18: 1 | AD18: 2 | AE18: 2 | AF18: 1 | AG18: 2 | AH18: 3 | AI18: 2 | AJ18: 2 | AK18: 1 | AL18: 2 | AM18: 2 | AN18: 1 | AO18: 1 | AP18: 1 | AQ18: 2 | AR18: 4 | AS18: 2 | AT18: 1 | AU18: 1 | AV18: 1 | AW18: 2 | AX18: 1 | AY18: 1 | AZ18: 2 | BA18: 3 | BB18: 3 | BC18: 3 | BD18: 1 | BE18: 3 | BF18: 3 | BG18: 1 | BH18: 1 | BI18: 2 | BJ18: 1 | BK18: 2 | BL18: 2 | BM18: 3
A19: Switzerland | B19: 2 | C19: 2 | D19: 2 | E19: 2 | F19: 4 | G19: 3 | H19: 1 | I19: 4 | J19: 1 | K19: 2 | L19: 1 | M19: 1 | N19: 1 | O19: 4 | P19: 4 | Q19: 2 | R19: 2 | S19: 4 | T19: 4 | U19: 2 | V19: 2 | W19: 1 | X19: 4 | Y19: 4 | Z19: 1 | AA19: 1 | AB19: 1 | AC19: 1 | AD19: 1 | AE19: 1 | AF19: 0 | AG19: 2 | AH19: 4 | AI19: 4 | AJ19: 4 | AK19: 4 | AL19: 4 | AM19: 4 | AN19: 2 | AO19: 2 | AP19: 2 | AQ19: 1 | AR19: 4 | AS19: 1 | AT19: 2 | AU19: 2 | AV19: 2 | AW19: 2 | AX19: 4 | AY19: 4 | AZ19: 4 | BA19: 3 | BB19: 3 | BC19: 3 | BD19: 0 | BE19: 0 | BF19: 3 | BG19: 1 | BH19: 1 | BI19: 2 | BJ19: 2 | BK19: 2 | BL19: 2 | BM19: 2
A20: Chile | B20: 2 | C20: 2 | D20: 0 | E20: 0 | F20: 3 | G20: 2 | H20: 1 | I20: 4 | J20: 1 | K20: 2 | L20: 2 | M20: 2 | N20: 1 | O20: 3 | P20: 3 | Q20: 3 | R20: 2 | S20: 3 | T20: 3 | U20: 2 | V20: 2 | W20: 2 | X20: 1 | Y20: 2 | Z20: 2 | AA20: 1 | AB20: 2 | AC20: 2 | AD20: 2 | AE20: 2 | AF20: 1 | AG20: 4 | AH20: 3 | AI20: 3 | AJ20: 3 | AK20: 1 | AL20: 3 | AM20: 3 | AN20: 1 | AO20: 2 | AP20: 1 | AQ20: 2 | AR20: 2 | AS20: 1 | AT20: 2 | AU20: 2 | AV20: 2 | AW20: 2 | AX20: 2 | AY20: 1 | AZ20: 4 | BA20: 3 | BB20: 3 | BC20: 3 | BD20: 1 | BE20: 3 | BF20: 1 | BG20: 1 | BH20: 1 | BI20: 0 | BJ20: 2 | BK20: 2 | BL20: 2 | BM20: 2
A21: Ethiopia | B21: 2 | C21: 1 | D21: 2 | E21: 1 | F21: 2 | G21: 3 | H21: 3 | I21: 3 | J21: 1 | K21: 2 | L21: 1 | M21: 2 | N21: 2 | O21: 2 | P21: 2 | Q21: 2 | R21: 1 | S21: 1 | T21: 1 | U21: 0 | AA21: 1 | AB21: 1 | AC21: 1 | AD21: 1 | AE21: 1 | AF21: 1 | AG21: 1 | AH21: 2 | AI21: 1 | AJ21: 1 | AK21: 2 | AL21: 1 | AM21: 2 | AN21: 1 | AO21: 1 | AP21: 1 | AQ21: 2 | AR21: 1 | AS21: 1 | AT21: 1 | AU21: 1 | AV21: 1 | AW21: 1 | AX21: 1 | AY21: 1 | AZ21: 3 | BA21: 3 | BB21: 3 | BC21: 3 | BD21: 1 | BE21: 2 | BF21: 0 | BG21: 1 | BH21: 1 | BI21: 2 | BJ21: 2 | BK21: 2 | BL21: 2 | BM21: 3
A22: Uganda | B22: 1 | C22: 1 | D22: 2 | E22: 2 | F22: 3 | G22: 3 | H22: 2 | I22: 4 | J22: 2 | K22: 2 | L22: 1 | M22: 2 | N22: 1 | O22: 2 | P22: 1 | Q22: 1 | R22: 1 | S22: 1 | T22: 2 | U22: 1 | AA22: 1 | AB22: 1 | AC22: 1 | AD22: 1 | AE22: 2 | AF22: 1 | AG22: 2 | AH22: 2 | AI22: 1 | AJ22: 1 | AK22: 1 | AL22: 1 | AM22: 4 | AN22: 1 | AO22: 1 | AP22: 1 | AQ22: 2 | AR22: 1 | AS22: 1 | AT22: 1 | AU22: 1 | AV22: 2 | AW22: 1 | AX22: 2 | AY22: 1 | AZ22: 4 | BA22: 1 | BB22: 3 | BC22: 3 | BD22: 1 | BE22: 3 | BF22: 1 | BG22: 1 | BH22: 0 | BI22: 1 | BJ22: 2 | BK22: 2 | BL22: 2 | BM22: 3
A23: Uzbekistan | B23: 2 | C23: 2 | D23: 1 | E23: 2 | F23: 2 | G23: 2 | H23: 1 | I23: 3 | J23: 1 | K23: 2 | L23: 1 | M23: 2 | N23: 1 | O23: 2 | P23: 2 | Q23: 2 | R23: 1 | S23: 1 | T23: 1 | U23: 2 | V23: 0 | X23: 0 | Y23: 0 | Z23: 0 | AA23: 1 | AB23: 1 | AC23: 1 | AD23: 1 | AE23: 1 | AF23: 1 | AG23: 1 | AH23: 3 | AI23: 3 | AJ23: 3 | AK23: 3 | AL23: 2 | AM23: 3 | AN23: 2 | AO23: 1 | AP23: 2 | AQ23: 2 | AR23: 2 | AS23: 1 | AT23: 1 | AU23: 1 | AV23: 1 | AW23: 1 | AX23: 1 | AY23: 1 | AZ23: 4 | BA23: 3 | BB23: 0 | BC23: 3 | BD23: 1 | BE23: 1 | BF23: 0 | BG23: 1 | BH23: 1 | BI23: 1 | BJ23: 2 | BK23: 3 | BL23: 3 | BM23: 3
A24: Türkiye | B24: 2 | C24: 2 | D24: 1 | E24: 1 | F24: 3 | G24: 1 | H24: 1 | I24: 4 | J24: 2 | K24: 2 | L24: 2 | M24: 2 | N24: 2 | O24: 0 | P24: 4 | Q24: 2 | R24: 1 | S24: 1 | T24: 1 | U24: 2 | V24: 2 | W24: 1 | X24: 3 | Y24: 0 | Z24: 0 | AA24: 1 | AB24: 1 | AC24: 1 | AD24: 0 | AE24: 0 | AF24: 1 | AG24: 1 | AH24: 4 | AI24: 4 | AJ24: 0 | AK24: 0 | AL24: 4 | AM24: 1 | AN24: 1 | AO24: 1 | AP24: 1 | AQ24: 1 | AR24: 1 | AS24: 1 | AT24: 1 | AU24: 4 | AV24: 4 | AW24: 4 | AX24: 4 | AY24: 1 | AZ24: 4 | BA24: 3 | BB24: 1 | BC24: 3 | BD24: 1 | BE24: 3 | BF24: 1 | BG24: 0 | BH24: 0 | BI24: 0 | BJ24: 2 | BK24: 2 | BL24: 2 | BM24: 2
A25: Argentina | B25: 2 | C25: 2 | D25: 2 | E25: 0 | F25: 3 | G25: 2 | H25: 2 | I25: 3 | J25: 1 | K25: 2 | L25: 2 | M25: 2 | O25: 2 | P25: 3 | Q25: 3 | R25: 2 | S25: 2 | T25: 1 | U25: 2 | V25: 1 | X25: 1 | Y25: 4 | Z25: 2 | AA25: 2 | AB25: 2 | AC25: 2 | AD25: 2 | AE25: 2 | AF25: 1 | AG25: 4 | AH25: 3 | AI25: 3 | AJ25: 3 | AK25: 2 | AL25: 2 | AM25: 2 | AN25: 1 | AO25: 1 | AP25: 2 | AQ25: 2 | AR25: 2 | AS25: 2 | AT25: 2 | AU25: 2 | AV25: 2 | AW25: 4 | AX25: 2 | AY25: 1 | AZ25: 3 | BA25: 3 | BB25: 3 | BC25: 3 | BD25: 1 | BE25: 0 | BF25: 0 | BG25: 2 | BH25: 2 | BI25: 0 | BJ25: 1 | BK25: 2 | BL25: 2 | BM25: 3
A26: Romania | B26: 2 | C26: 2 | D26: 2 | E26: 2 | F26: 2 | G26: 3 | H26: 4 | I26: 4 | J26: 2 | K26: 1 | L26: 2 | M26: 2 | N26: 2 | O26: 3 | P26: 3 | Q26: 2 | R26: 2 | S26: 2 | T26: 2 | U26: 2 | X26: 3 | Y26: 3 | Z26: 2 | AA26: 2 | AB26: 1 | AC26: 1 | AD26: 2 | AE26: 1 | AF26: 1 | AG26: 1 | AH26: 4 | AI26: 4 | AJ26: 3 | AK26: 3 | AL26: 2 | AM26: 2 | AN26: 1 | AO26: 2 | AP26: 1 | AQ26: 1 | AR26: 4 | AS26: 1 | AT26: 2 | AU26: 1 | AV26: 4 | AW26: 4 | AX26: 4 | AY26: 1 | AZ26: 3 | BA26: 3 | BB26: 3 | BC26: 3 | BD26: 1 | BE26: 3 | BF26: 1 | BG26: 1 | BH26: 1 | BI26: 1 | BJ26: 2 | BK26: 3 | BL26: 3 | BM26: 3
A27: UK | B27: 2 | C27: 2 | D27: 1 | E27: 2 | F27: 3 | G27: 2 | H27: 1 | I27: 4 | J27: 2 | K27: 2 | L27: 2 | M27: 2 | N27: 2 | O27: 4 | P27: 4 | Q27: 4 | R27: 2 | S27: 2 | T27: 1 | U27: 2 | V27: 2 | W27: 2 | X27: 2 | Y27: 4 | Z27: 2 | AA27: 1 | AB27: 2 | AC27: 0 | AD27: 2 | AE27: 2 | AF27: 0 | AG27: 1 | AH27: 4 | AI27: 4 | AJ27: 3 | AK27: 0 | AL27: 4 | AM27: 0 | AN27: 2 | AO27: 0 | AP27: 1 | AQ27: 2 | AR27: 4 | AS27: 2 | AT27: 1 | AU27: 1 | AV27: 1 | AW27: 2 | AX27: 1 | AY27: 4 | AZ27: 3 | BA27: 3 | BB27: 3 | BC27: 3 | BD27: 1 | BE27: 0 | BF27: 1 | BG27: 1 | BH27: 1 | BI27: 0 | BJ27: 2 | BK27: 2 | BL27: 2 | BM27: 2
A28: Saudi Arabia | B28: 2 | C28: 2 | D28: 2 | E28: 2 | F28: 3 | G28: 1 | H28: 1 | I28: 1 | J28: 2 | K28: 2 | L28: 2 | M28: 1 | N28: 2 | O28: 0 | P28: 2 | Q28: 2 | R28: 2 | S28: 2 | T28: 2 | U28: 2 | V28: 2 | W28: 0 | X28: 0 | Y28: 0 | Z28: 2 | AA28: 2 | AB28: 2 | AC28: 2 | AD28: 1 | AE28: 1 | AF28: 0 | AG28: 3 | AH28: 4 | AI28: 4 | AJ28: 4 | AK28: 4 | AL28: 4 | AM28: 0 | AN28: 2 | AO28: 2 | AP28: 2 | AQ28: 2 | AR28: 4 | AS28: 3 | AT28: 1 | AU28: 1 | AV28: 3 | AW28: 4 | AX28: 2 | AY28: 1 | AZ28: 2 | BA28: 3 | BB28: 0 | BC28: 3 | BD28: 0 | BE28: 3 | BF28: 0 | BG28: 1 | BH28: 1 | BI28: 1 | BJ28: 2 | BK28: 2 | BL28: 2 | BM28: 3
A29: Ukraine | B29: 2 | C29: 2 | D29: 0 | E29: 2 | F29: 3 | G29: 2 | H29: 1 | I29: 3 | J29: 2 | K29: 2 | L29: 2 | M29: 2 | N29: 1 | O29: 4 | P29: 4 | Q29: 3 | R29: 1 | S29: 2 | T29: 3 | U29: 2 | V29: 0 | X29: 0 | Y29: 4 | Z29: 1 | AA29: 2 | AB29: 1 | AC29: 1 | AD29: 1 | AE29: 1 | AF29: 1 | AG29: 3 | AH29: 4 | AI29: 0 | AJ29: 0 | AK29: 3 | AL29: 4 | AM29: 0 | AN29: 1 | AO29: 1 | AP29: 1 | AQ29: 2 | AR29: 4 | AS29: 1 | AT29: 2 | AU29: 2 | AV29: 1 | AW29: 2 | AX29: 4 | AY29: 1 | AZ29: 2 | BA29: 3 | BB29: 3 | BC29: 3 | BD29: 1 | BE29: 3 | BF29: 1 | BG29: 1 | BH29: 1 | BI29: 1 | BJ29: 2 | BK29: 2 | BL29: 2 | BM29: 2
A30: Ghana | B30: 1 | C30: 1 | D30: 1 | E30: 1 | F30: 2 | G30: 3 | H30: 2 | I30: 2 | J30: 2 | K30: 2 | L30: 2 | M30: 2 | N30: 2 | O30: 2 | P30: 2 | Q30: 2 | R30: 2 | S30: 2 | T30: 2 | U30: 1 | AA30: 1 | AB30: 1 | AC30: 1 | AD30: 1 | AE30: 1 | AF30: 1 | AG30: 2 | AH30: 1 | AI30: 2 | AJ30: 2 | AK30: 2 | AL30: 2 | AM30: 3 | AN30: 1 | AO30: 1 | AP30: 1 | AQ30: 2 | AR30: 1 | AS30: 1 | AT30: 1 | AU30: 1 | AV30: 1 | AX30: 1 | AY30: 1 | AZ30: 3 | BA30: 3 | BB30: 3 | BC30: 3 | BD30: 3 | BE30: 3 | BF30: 1 | BG30: 2 | BH30: 2 | BI30: 2 | BJ30: 2 | BK30: 2 | BL30: 2 | BM30: 3
A31: Indonesia | B31: 2 | C31: 0 | D31: 1 | E31: 1 | F31: 1 | G31: 3 | H31: 2 | I31: 3 | J31: 1 | K31: 1 | L31: 1 | M31: 1 | N31: 1 | O31: 1 | P31: 0 | Q31: 1 | R31: 1 | S31: 1 | T31: 1 | U31: 0 | AA31: 1 | AB31: 1 | AC31: 1 | AD31: 2 | AE31: 2 | AF31: 1 | AG31: 2 | AH31: 2 | AI31: 1 | AJ31: 1 | AK31: 0 | AL31: 1 | AM31: 1 | AN31: 1 | AO31: 1 | AP31: 1 | AQ31: 1 | AR31: 1 | AS31: 1 | AT31: 1 | AU31: 1 | AV31: 1 | AW31: 1 | AX31: 1 | AY31: 1 | AZ31: 1 | BA31: 1 | BB31: 3 | BC31: 1 | BD31: 1 | BE31: 1 | BF31: 1 | BG31: 1 | BH31: 1 | BI31: 2 | BJ31: 0 | BK31: 2 | BL31: 2 | BM31: 2
A32: Brazil | B32: 2 | C32: 2 | D32: 2 | E32: 2 | F32: 3 | G32: 1 | H32: 1 | I32: 4 | J32: 2 | K32: 2 | L32: 1 | M32: 2 | N32: 2 | O32: 4 | P32: 3 | Q32: 3 | R32: 2 | S32: 2 | T32: 2 | U32: 2 | V32: 0 | X32: 3 | Y32: 1 | Z32: 3 | AA32: 2 | AB32: 2 | AC32: 2 | AD32: 2 | AE32: 2 | AF32: 1 | AG32: 3 | AH32: 2 | AI32: 2 | AJ32: 2 | AK32: 2 | AL32: 2 | AM32: 2 | AN32: 2 | AO32: 1 | AP32: 2 | AQ32: 2 | AR32: 3 | AS32: 0 | AT32: 2 | AU32: 3 | AV32: 2 | AW32: 3 | AX32: 2 | AY32: 1 | AZ32: 2 | BA32: 3 | BB32: 3 | BC32: 1 | BD32: 1 | BE32: 3 | BF32: 0 | BG32: 1 | BH32: 1 | BI32: 1 | BJ32: 2 | BK32: 3 | BL32: 3 | BM32: 3
A33: Kenya | B33: 1 | C33: 1 | D33: 2 | E33: 2 | F33: 2 | G33: 3 | H33: 2 | I33: 4 | J33: 1 | K33: 0 | L33: 1 | M33: 2 | N33: 2 | O33: 1 | P33: 2 | Q33: 1 | R33: 1 | S33: 1 | T33: 1 | U33: 1 | AA33: 1 | AB33: 1 | AC33: 1 | AD33: 1 | AE33: 2 | AF33: 1 | AG33: 1 | AH33: 2 | AI33: 2 | AK33: 2 | AL33: 2 | AM33: 1 | AN33: 1 | AO33: 1 | AP33: 1 | AQ33: 1 | AR33: 1 | AS33: 1 | AT33: 1 | AU33: 1 | AV33: 1 | AW33: 1 | AX33: 1 | AY33: 1 | AZ33: 4 | BA33: 3 | BB33: 3 | BC33: 3 | BD33: 3 | BE33: 3 | BF33: 3 | BG33: 2 | BH33: 2 | BI33: 2 | BJ33: 2 | BK33: 2 | BL33: 2 | BM33: 3
A34: Austria | B34: 2 | C34: 2 | D34: 2 | E34: 1 | F34: 4 | G34: 2 | H34: 2 | I34: 4 | J34: 2 | K34: 2 | L34: 2 | M34: 2 | N34: 1 | O34: 3 | P34: 3 | Q34: 2 | R34: 1 | S34: 4 | T34: 3 | U34: 2 | V34: 0 | X34: 0 | Y34: 2 | Z34: 1 | AA34: 1 | AB34: 2 | AC34: 1 | AD34: 1 | AE34: 1 | AF34: 1 | AG34: 2 | AH34: 4 | AI34: 4 | AJ34: 4 | AK34: 1 | AL34: 4 | AM34: 4 | AN34: 2 | AO34: 1 | AP34: 1 | AQ34: 1 | AR34: 4 | AS34: 3 | AT34: 2 | AU34: 1 | AV34: 1 | AW34: 1 | AX34: 1 | AY34: 3 | AZ34: 3 | BA34: 1 | BB34: 3 | BC34: 3 | BD34: 1 | BE34: 1 | BF34: 1 | BG34: 1 | BH34: 1 | BI34: 0 | BJ34: 1 | BK34: 2 | BL34: 2 | BM34: 2
A35: Madagascar | B35: 2 | C35: 1 | D35: 2 | E35: 1 | F35: 2 | G35: 4 | H35: 2 | I35: 2 | J35: 1 | K35: 2 | L35: 1 | M35: 2 | N35: 1 | O35: 1 | P35: 1 | Q35: 1 | R35: 1 | S35: 1 | T35: 1 | U35: 1 | AA35: 1 | AB35: 1 | AC35: 1 | AD35: 1 | AE35: 2 | AF35: 1 | AG35: 1 | AH35: 1 | AI35: 1 | AJ35: 1 | AK35: 1 | AL35: 1 | AM35: 1 | AN35: 1 | AO35: 1 | AP35: 1 | AQ35: 1 | AR35: 1 | AS35: 1 | AT35: 1 | AU35: 1 | AV35: 1 | AW35: 1 | AX35: 1 | AY35: 1 | AZ35: 4 | BA35: 1 | BB35: 2 | BC35: 3 | BD35: 1 | BE35: 1 | BF35: 1 | BG35: 2 | BH35: 2 | BI35: 1 | BJ35: 1 | BK35: 2 | BL35: 2 | BM35: 2
A36: Canada | B36: 2 | C36: 2 | D36: 2 | E36: 2 | F36: 4 | G36: 1 | H36: 1 | I36: 0 | J36: 1 | K36: 2 | L36: 1 | M36: 1 | N36: 1 | O36: 4 | P36: 4 | Q36: 3 | R36: 2 | S36: 4 | T36: 2 | U36: 2 | V36: 2 | W36: 4 | X36: 4 | Y36: 0 | Z36: 3 | AA36: 1 | AB36: 2 | AC36: 1 | AD36: 1 | AE36: 1 | AF36: 2 | AG36: 4 | AH36: 4 | AI36: 4 | AJ36: 4 | AK36: 4 | AL36: 0 | AM36: 4 | AN36: 2 | AO36: 2 | AP36: 2 | AQ36: 2 | AR36: 4 | AS36: 0 | AT36: 2 | AU36: 4 | AV36: 0 | AW36: 4 | AX36: 0 | AY36: 1 | AZ36: 3 | BA36: 3 | BB36: 3 | BC36: 3 | BD36: 1 | BE36: 3 | BF36: 3 | BG36: 1 | BH36: 1 | BI36: 0 | BJ36: 2 | BK36: 2 | BL36: 2 | BM36: 2
A37: Hong Kong | B37: 2 | C37: 2 | D37: 2 | E37: 2 | F37: 3 | G37: 3 | H37: 2 | I37: 2 | J37: 2 | K37: 1 | L37: 2 | M37: 1 | N37: 2 | O37: 2 | P37: 3 | Q37: 3 | R37: 3 | S37: 2 | T37: 2 | U37: 2 | V37: 2 | W37: 3 | X37: 3 | Y37: 3 | Z37: 3 | AA37: 2 | AB37: 2 | AC37: 1 | AD37: 2 | AE37: 1 | AF37: 2 | AG37: 2 | AH37: 3 | AI37: 3 | AJ37: 3 | AK37: 3 | AL37: 3 | AM37: 3 | AN37: 2 | AO37: 2 | AP37: 2 | AQ37: 2 | AR37: 2 | AS37: 2 | AT37: 2 | AU37: 2 | AV37: 2 | AW37: 2 | AX37: 3 | AY37: 1 | AZ37: 1 | BA37: 3 | BB37: 2 | BC37: 3 | BD37: 2 | BE37: 3 | BF37: 3 | BG37: 1 | BH37: 1 | BI37: 1 | BJ37: 2 | BK37: 1 | BL37: 3 | BM37: 3
A38: Croatia | B38: 2 | C38: 2 | D38: 1 | E38: 2 | F38: 4 | G38: 2 | H38: 2 | I38: 4 | J38: 2 | K38: 2 | L38: 2 | M38: 2 | N38: 2 | O38: 4 | P38: 4 | Q38: 4 | R38: 4 | S38: 3 | T38: 3 | U38: 2 | V38: 2 | W38: 4 | X38: 4 | Y38: 0 | Z38: 2 | AA38: 2 | AB38: 1 | AC38: 1 | AD38: 1 | AE38: 1 | AF38: 0 | AG38: 2 | AH38: 4 | AI38: 4 | AJ38: 4 | AK38: 4 | AL38: 4 | AM38: 4 | AN38: 1 | AO38: 2 | AP38: 1 | AQ38: 2 | AR38: 4 | AS38: 1 | AT38: 2 | AU38: 4 | AV38: 4 | AW38: 4 | AX38: 4 | AY38: 2 | AZ38: 2 | BA38: 3 | BB38: 3 | BC38: 3 | BD38: 1 | BE38: 3 | BF38: 1 | BG38: 1 | BH38: 1 | BI38: 1 | BJ38: 2 | BK38: 3 | BL38: 3 | BM38: 4
A39: New Zealand | B39: 2 | C39: 2 | D39: 2 | E39: 2 | F39: 4 | G39: 3 | H39: 3 | I39: 4 | J39: 2 | K39: 2 | L39: 1 | M39: 2 | N39: 1 | O39: 3 | P39: 3 | Q39: 2 | R39: 2 | S39: 2 | T39: 2 | U39: 2 | V39: 2 | W39: 2 | X39: 4 | Y39: 4 | Z39: 1 | AA39: 0 | AB39: 1 | AC39: 1 | AD39: 2 | AE39: 2 | AF39: 1 | AG39: 2 | AH39: 4 | AI39: 4 | AJ39: 3 | AK39: 1 | AL39: 4 | AM39: 3 | AN39: 2 | AO39: 2 | AP39: 2 | AQ39: 2 | AR39: 3 | AS39: 3 | AT39: 2 | AU39: 1 | AV39: 1 | AW39: 2 | AX39: 1 | AY39: 2 | AZ39: 3 | BA39: 3 | BB39: 3 | BC39: 3 | BD39: 1 | BE39: 3 | BF39: 3 | BG39: 0 | BH39: 0 | BI39: 2 | BJ39: 1 | BK39: 1 | BL39: 2 | BM39: 2
A40: Germany | B40: 2 | C40: 2 | D40: 2 | E40: 2 | F40: 4 | G40: 2 | H40: 1 | I40: 4 | J40: 2 | K40: 2 | L40: 1 | M40: 2 | N40: 1 | O40: 4 | P40: 4 | Q40: 0 | R40: 0 | S40: 4 | T40: 4 | U40: 2 | V40: 2 | W40: 4 | X40: 4 | Y40: 3 | Z40: 1 | AA40: 2 | AB40: 1 | AC40: 2 | AD40: 1 | AE40: 1 | AF40: 0 | AG40: 2 | AH40: 4 | AI40: 4 | AJ40: 4 | AK40: 2 | AL40: 4 | AM40: 4 | AN40: 2 | AO40: 2 | AP40: 2 | AQ40: 1 | AR40: 4 | AS40: 0 | AT40: 4 | AU40: 2 | AV40: 4 | AW40: 2 | AX40: 0 | AY40: 4 | AZ40: 0 | BA40: 3 | BB40: 3 | BC40: 3 | BD40: 2 | BE40: 3 | BF40: 3 | BG40: 1 | BH40: 1 | BI40: 0 | BJ40: 0 | BK40: 3 | BL40: 3 | BM40: 2
...

Sheet scales
A1: ID | B1: edu_daycare_law | C1: edu_daycare_inclusive | D1: edu_school_adapt | E1: edu_school_inclusive | F1: edu_law_freepostsecondary | G1: edu_daycare_access | H1: edu_school_enroll | I1: edu_inclusion | J1: edu_inclusion2 | K1: edu_curriculum_adapted | L1: edu_teacher_training | M1: comm_sports | N1: comm_non_sports | O1: comm_sports_inclusive | P1: comm_non_sports_inclusive | Q1: comm_family_learn | R1: comm_neglang_people | S1: comm_neglang_media | T1: comm_kept | U1: indep_transition | V1: indep_transport | W1: indep_edu_relationships | X1: indep_employer_accom | Y1: indep_govt_fin | Z1: indep_volunteer | AA1: indep_work_paid | AB1: indep_work_minwage | AC1: indep_work_20hr | AD1: indep_work_inclusive | AE1: indep_work_benefits | AF1: indep_livingexp | AG1: indep_exclude | AH1: health_prenatal | AI1: health_nipt | AJ1: health_nips_paid | AK1: health_prenatal_paid | AL1: health_terminate | AM1: health_prenatal_info | AN1: health_guidelines | AO1: clinic_children | AP1: clinic_adults | AQ1: health_exp | AR1: healthy_qual | AS1: health_events_plan | AT1: health_speech | AU1: health_heart | AV1: health_hearing_test | AW1: health_hearing_treat | AX1: health_mental | AY1: health_afford | AZ1: health_birthcontrol | BA1: policy_edu | BB1: policy_vote | BC1: policy_nondiscrimination | BD1: policy_marry | BE1: policy_abuse_invest | BF1: policy_sterilization | BG1: policy_abandonunder | BH1: policy_abandonover | BI1: policy_abuse | BJ1: policy_openinput | BK1: comm_electricity | BL1: comm_sanitation | BM1: policy_influence
A2: Scale | B2: Yes | No | Do not know | C2: Yes | No | Do not know | D2: Yes | No | Do not know | E2: Yes | No | Do not know | F2: Yes | No | Do not know | G2: None or Few | Some | Many | Most or All | Do not know | H2: None or Few | Some | Many | Most or All | Do not know | I2: None or Few | Some | Many | Most or All | Do not know | J2: None or Few | Some | Many | Most or All | Do not know | K2: None or Few | Some | Many | Most or All | Do not know | L2: None or Few | Some | Many | Most or All | Do not know | M2: Yes | No | Do not know | N2: Yes | No | Do not know | O2: Yes | No | Do not know | P2: Yes | No | Do not know | Q2: None or Few | Some | Many | Most or All | Do not know | R2: None or Few | Some | Many | Most or All | Do not know | S2: None or Few | Some | Many | Most or All | Do not know | T2: None or Few | Some | Many | Most or All | Do not know | U2: Yes | No | Do not know | V2: Yes | No | Do not know | W2: Yes | No | Do not know | X2: Yes | No | Do not know | Y2: None or Few | Some | Many | Most or All | Do not know | Z2: None or Few | Some | Many | Most or All | Do not know | AA2: None or Few | Some | Many | Most or All | Do not know | AB2: None or Few | Some | Many | Most or All | Do not know | AC2: None or Few | Some | Many | Most or All | Do not know | AD2: None or Few | Some | Many | Most or All | Do not know | AE2: None or Few | Some | Many | Most or All | Do not know | AF2: None or Few | Some | Many | Most or All | Do not know | AG2: None or Few | Some | Many | Most or All | Do not know | AH2: Yes | No | Do not know | AI2: Yes | No | Do not know | AJ2: None or Few | Some | Many | Most or All | Do not know | AK2: None or Few | Some | Many | Most or All | Do not know | AL2: None or Few | Some | Many | Most or All | Do not know | AM2: None or Few | Some | Many | Most or All | Do not know | AN2: Yes | No | Do not know | AO2: Yes | No | Do not know | AP2: Yes | No | Do not know | AQ2: Yes | No | Do not know | AR2: Yes | No | Do not know | AS2: Yes | No | Do not know | AT2: None or Few | Some | Many | Most or All | Do not know | AU2: None or Few | Some | Many | Most or All | Do not know | AV2: None or Few | Some | Many | Most or All | Do not know | AW2: None or Few | Some | Many | Most or All | Do not know | AX2: None or Few | Some | Many | Most or All | Do not know | AY2: None or Few | Some | Many | Most or All | Do not know | AZ2: None or Few | Some | Many | Most or All | Do not know | BA2: Yes - in all regions/states/provinces | Yes - in some regions/states/provinces | No | Do not know | BB2: Yes - in all regions/states/provinces | Yes - in some regions/states/provinces | No | Do not know | BC2: Yes - in all regions/states/provinces | Yes - in some regions/states/provinces | No | Do not know | BD2: Yes - in all regions/states/provinces | Yes - in some regions/states/provinces | No | Do not know | BE2: Yes - in all regions/states/provinces | Yes - in some regions/states/provinces | No | Do not know | BF2: Yes - in all regions/states/provinces | Yes - in some regions/states/provinces | No | Do not know | BG2: Yes | No | Do not know | BH2: Yes | No | Do not know | BI2: Yes | No | Do not know | BJ2: Yes | No | Do not know | BK2: Less | Same | More | Do not know | BL2: Less | Same | More | Do not know | BM2: None | Little | Some | A lot | Do not know
B5: Yes | No | Do not know | C5: None or Few | Some | Many | Most or All | Do not know | D5: Yes - in all regions/states/provinces | Yes - in some regions/states/provinces | No | Do not know | E5: Less | Same | More | Do not know | F5: None | Little | Some | A lot | Do not know
A6: 0 | B6: Do not know | C6: Do not know | D6: Do not know | E6: Do not know | F6: Do not know
A7: 1 | B7: No | C7: None or Few | D7: No | E7: Less | F7: None
A8: 2 | B8: Yes | C8: Some | D8: Yes - in some regions/states/provinces | E8: Same | F8: Little
A9: 3 | C9: Many | D9: Yes - in all regions/states/provinces | E9: More | F9: Some
A10: 4 | C10: Most or All | F10: A lot

Sheet transformed
A1: {=raw!A1:A49} -> region | B1: {=raw!B1:BM1} -> comm_sports | C1: comm_non_sports | D1: comm_sports_inclusive | E1: comm_non_sports_inclusive | F1: comm_family_learn | G1: comm_neglang_people | H1: comm_neglang_media | I1: comm_kept | J1: edu_daycare_law | K1: edu_daycare_inclusive | L1: edu_school_adapt | M1: edu_school_inclusive | N1: edu_law_freepostsecondary | O1: edu_daycare_access | P1: edu_school_enroll | Q1: edu_inclusion | R1: edu_inclusion2 | S1: edu_curriculum_adapted | T1: edu_teacher_training | U1: health_prenatal | V1: health_nipt | W1: health_nips_paid | X1: health_prenatal_paid | Y1: health_terminate | Z1: health_prenatal_info | AA1: health_guidelines | AB1: clinic_children | AC1: clinic_adults | AD1: health_exp | AE1: healthy_qual | AF1: health_events_plan | AG1: health_speech | AH1: health_heart | AI1: health_hearing_test | AJ1: health_hearing_treat | AK1: health_mental | AL1: health_afford | AM1: health_birthcontrol | AN1: indep_transition | AO1: indep_transport | AP1: indep_edu_relationships | AQ1: indep_employer_accom | AR1: indep_govt_fin | AS1: indep_volunteer | AT1: indep_work_paid | AU1: indep_work_minwage | AV1: indep_work_20hr | AW1: indep_work_inclusive | AX1: indep_work_benefits | AY1: indep_livingexp | AZ1: indep_exclude | BA1: policy_edu | BB1: policy_vote | BC1: policy_nondiscrimination | BD1: policy_marry | BE1: policy_abuse_invest | BF1: policy_sterilization | BG1: policy_abandonunder | BH1: policy_abandonover | BI1: policy_abuse | BJ1: policy_openinput | BK1: comm_electricity | BL1: comm_sanitation | BM1: policy_influence
A2: Peru | B2: =IF(raw!B2="","",INDEX(scales!$B$6:$F$10, MATCH(_xlfn.NUMBERVALUE(raw!B2),scales!$A$6:$A$10,0), MATCH( _xlfn.XLOOKUP(raw!B$1,scales!$1:$1,scales!$2:$2), scales!$B$5:$F$5, 0 ) )) -> Yes | C2: =IF(raw!C2="","",INDEX(scales!$B$6:$F$10, MATCH(_xlfn.NUMBERVALUE(raw!C2),scales!$A$6:$A$10,0), MATCH( _xlfn.XLOOKUP(raw!C$1,scales!$1:$1,scales!$2:$2), scales!$B$5:$F$5, 0 ) )) -> Yes | D2: =IF(raw!D2="","",INDEX(scales!$B$6:$F$10, MATCH(_xlfn.NUMBERVALUE(raw!D2),scales!$A$6:$A$10,0), MATCH( _xlfn.XLOOKUP(raw!D$1,scales!$1:$1,scales!$2:$2), scales!$B$5:$F$5, 0 ) )) -> Yes | E2: =IF(raw!E2="","",INDEX(scales!$B$6:$F$10, MATCH(_xlfn.NUMBERVALUE(raw!E2),scales!$A$6:$A$10,0), MATCH( _xlfn.XLOOKUP(raw!E$1,scales!$1:$1,scales!$2:$2), scales!$B$5:$F$5, 0 ) )) -> Yes | F2: =IF(raw!F2="","",INDEX(scales!$B$6:$F$10, MATCH(_xlfn.NUMBERVALUE(raw!F2),scales!$A$6:$A$10,0), MATCH( _xlfn.XLOOKUP(raw!F$1,scales!$1:$1,scales!$2:$2), scales!$B$5:$F$5, 0 ) )) -> Most or All | G2: =IF(raw!G2="","",INDEX(scales!$B$6:$F$10, MATCH(_xlfn.NUMBERVALUE(raw!G2),scales!$A$6:$A$10,0), MATCH( _xlfn.XLOOKUP(raw!G$1,scales!$1:$1,scales!$2:$2), scales!$B$5:$F$5, 0 ) )) -> Many | H2: =IF(raw!H2="","",INDEX(scales!$B$6:$F$10, MATCH(_xlfn.NUMBERVALUE(raw!H2),scales!$A$6:$A$10,0), MATCH( _xlfn.XLOOKUP(raw!H$1,scales!$1:$1,scales!$2:$2), scales!$B$5:$F$5, 0 ) )) -> Some | I2: =IF(raw!I2="","",INDEX(scales!$B$6:$F$10, MATCH(_xlfn.NUMBERVALUE(raw!I2),scales!$A$6:$A$10,0), MATCH( _xlfn.XLOOKUP(raw!I$1,scales!$1:$1,scales!$2:$2), scales!$B$5:$F$5, 0 ) )) -> Many | ... BM2: =IF(raw!BM2="","",INDEX(scales!$B$6:$F$10, MATCH(_xlfn.NUMBERVALUE(raw!BM2),scales!$A$6:$A$10,0), MATCH( _xlfn.XLOOKUP(raw!BM$1,scales!$1:$1,scales!$2:$2), scales!$B$5:$F$5, 0 ) )) -> A lot
A3: Costa Rica | B3: =IF(raw!B3="","",INDEX(scales!$B$6:$F$10, MATCH(_xlfn.NUMBERVALUE(raw!B3),scales!$A$6:$A$10,0), MATCH( _xlfn.XLOOKUP(raw!B$1,scales!$1:$1,scales!$2:$2), scales!$B$5:$F$5, 0 ) )) -> Yes | C3: =IF(raw!C3="","",INDEX(scales!$B$6:$F$10, MATCH(_xlfn.NUMBERVALUE(raw!C3),scales!$A$6:$A$10,0), MATCH( _xlfn.XLOOKUP(raw!C$1,scales!$1:$1,scales!$2:$2), scales!$B$5:$F$5, 0 ) )) -> Yes | D3: =IF(raw!D3="","",INDEX(scales!$B$6:$F$10, MATCH(_xlfn.NUMBERVALUE(raw!D3),scales!$A$6:$A$10,0), MATCH( _xlfn.XLOOKUP(raw!D$1,scales!$1:$1,scales!$2:$2), scales!$B$5:$F$5, 0 ) )) -> Yes | E3: =IF(raw!E3="","",INDEX(scales!$B$6:$F$10, MATCH(_xlfn.NUMBERVALUE(raw!E3),scales!$A$6:$A$10,0), MATCH( _xlfn.XLOOKUP(raw!E$1,scales!$1:$1,scales!$2:$2), scales!$B$5:$F$5, 0 ) )) -> Yes | F3: =IF(raw!F3="","",INDEX(scales!$B$6:$F$10, MATCH(_xlfn.NUMBERVALUE(raw!F3),scales!$A$6:$A$10,0), MATCH( _xlfn.XLOOKUP(raw!F$1,scales!$1:$1,scales!$2:$2), scales!$B$5:$F$5, 0 ) )) -> Most or All | G3: =IF(raw!G3="","",INDEX(scales!$B$6:$F$10, MATCH(_xlfn.NUMBERVALUE(raw!G3),scales!$A$6:$A$10,0), MATCH( _xlfn.XLOOKUP(raw!G$1,scales!$1:$1,scales!$2:$2), scales!$B$5:$F$5, 0 ) )) -> Some | H3: =IF(raw!H3="","",INDEX(scales!$B$6:$F$10, MATCH(_xlfn.NUMBERVALUE(raw!H3),scales!$A$6:$A$10,0), MATCH( _xlfn.XLOOKUP(raw!H$1,scales!$1:$1,scales!$2:$2), scales!$B$5:$F$5, 0 ) )) -> None or Few | I3: =IF(raw!I3="","",INDEX(scales!$B$6:$F$10, MATCH(_xlfn.NUMBERVALUE(raw!I3),scales!$A$6:$A$10,0), MATCH( _xlfn.XLOOKUP(raw!I$1,scales!$1:$1,scales!$2:$2), scales!$B$5:$F$5, 0 ) )) -> Most or All | ... BM3: =IF(raw!BM3="","",INDEX(scales!$B$6:$F$10, MATCH(_xlfn.NUMBERVALUE(raw!BM3),scales!$A$6:$A$10,0), MATCH( _xlfn.XLOOKUP(raw!BM$1,scales!$1:$1,scales!$2:$2), scales!$B$5:$F$5, 0 ) )) -> Some
A4: Costa Rica | B4: =IF(raw!B4="","",INDEX(scales!$B$6:$F$10, MATCH(_xlfn.NUMBERVALUE(raw!B4),scales!$A$6:$A$10,0), MATCH( _xlfn.XLOOKUP(raw!B$1,scales!$1:$1,scales!$2:$2), scales!$B$5:$F$5, 0 ) )) -> Yes | C4: =IF(raw!C4="","",INDEX(scales!$B$6:$F$10, MATCH(_xlfn.NUMBERVALUE(raw!C4),scales!$A$6:$A$10,0), MATCH( _xlfn.XLOOKUP(raw!C$1,scales!$1:$1,scales!$2:$2), scales!$B$5:$F$5, 0 ) )) -> No | D4: =IF(raw!D4="","",INDEX(scales!$B$6:$F$10, MATCH(_xlfn.NUMBERVALUE(raw!D4),scales!$A$6:$A$10,0), MATCH( _xlfn.XLOOKUP(raw!D$1,scales!$1:$1,scales!$2:$2), scales!$B$5:$F$5, 0 ) )) -> Yes | E4: =IF(raw!E4="","",INDEX(scales!$B$6:$F$10, MATCH(_xlfn.NUMBERVALUE(raw!E4),scales!$A$6:$A$10,0), MATCH( _xlfn.XLOOKUP(raw!E$1,scales!$1:$1,scales!$2:$2), scales!$B$5:$F$5, 0 ) )) -> Yes | F4: =IF(raw!F4="","",INDEX(scales!$B$6:$F$10, MATCH(_xlfn.NUMBERVALUE(raw!F4),scales!$A$6:$A$10,0), MATCH( _xlfn.XLOOKUP(raw!F$1,scales!$1:$1,scales!$2:$2), scales!$B$5:$F$5, 0 ) )) -> Most or All | G4: =IF(raw!G4="","",INDEX(scales!$B$6:$F$10, MATCH(_xlfn.NUMBERVALUE(raw!G4),scales!$A$6:$A$10,0), MATCH( _xlfn.XLOOKUP(raw!G$1,scales!$1:$1,scales!$2:$2), scales!$B$5:$F$5, 0 ) )) -> Many | H4: =IF(raw!H4="","",INDEX(scales!$B$6:$F$10, MATCH(_xlfn.NUMBERVALUE(raw!H4),scales!$A$6:$A$10,0), MATCH( _xlfn.XLOOKUP(raw!H$1,scales!$1:$1,scales!$2:$2), scales!$B$5:$F$5, 0 ) )) -> Some | I4: =IF(raw!I4="","",INDEX(scales!$B$6:$F$10, MATCH(_xlfn.NUMBERVALUE(raw!I4),scales!$A$6:$A$10,0), MATCH( _xlfn.XLOOKUP(raw!I$1,scales!$1:$1,scales!$2:$2), scales!$B$5:$F$5, 0 ) )) -> Most or All | ... BM4: =IF(raw!BM4="","",INDEX(scales!$B$6:$F$10, MATCH(_xlfn.NUMBERVALUE(raw!BM4),scales!$A$6:$A$10,0), MATCH( _xlfn.XLOOKUP(raw!BM$1,scales!$1:$1,scales!$2:$2), scales!$B$5:$F$5, 0 ) )) -> A lot
A5: Chile | B5: =IF(raw!B5="","",INDEX(scales!$B$6:$F$10, MATCH(_xlfn.NUMBERVALUE(raw!B5),scales!$A$6:$A$10,0), MATCH( _xlfn.XLOOKUP(raw!B$1,scales!$1:$1,scales!$2:$2), scales!$B$5:$F$5, 0 ) )) -> Yes | C5: =IF(raw!C5="","",INDEX(scales!$B$6:$F$10, MATCH(_xlfn.NUMBERVALUE(raw!C5),scales!$A$6:$A$10,0), MATCH( _xlfn.XLOOKUP(raw!C$1,scales!$1:$1,scales!$2:$2), scales!$B$5:$F$5, 0 ) )) -> Yes | D5: =IF(raw!D5="","",INDEX(scales!$B$6:$F$10, MATCH(_xlfn.NUMBERVALUE(raw!D5),scales!$A$6:$A$10,0), MATCH( _xlfn.XLOOKUP(raw!D$1,scales!$1:$1,scales!$2:$2), scales!$B$5:$F$5, 0 ) )) -> Do not know | E5: =IF(raw!E5="","",INDEX(scales!$B$6:$F$10, MATCH(_xlfn.NUMBERVALUE(raw!E5),scales!$A$6:$A$10,0), MATCH( _xlfn.XLOOKUP(raw!E$1,scales!$1:$1,scales!$2:$2), scales!$B$5:$F$5, 0 ) )) -> Do not know | F5: =IF(raw!F5="","",INDEX(scales!$B$6:$F$10, MATCH(_xlfn.NUMBERVALUE(raw!F5),scales!$A$6:$A$10,0), MATCH( _xlfn.XLOOKUP(raw!F$1,scales!$1:$1,scales!$2:$2), scales!$B$5:$F$5, 0 ) )) -> Some | G5: =IF(raw!G5="","",INDEX(scales!$B$6:$F$10, MATCH(_xlfn.NUMBERVALUE(raw!G5),scales!$A$6:$A$10,0), MATCH( _xlfn.XLOOKUP(raw!G$1,scales!$1:$1,scales!$2:$2), scales!$B$5:$F$5, 0 ) )) -> None or Few | H5: =IF(raw!H5="","",INDEX(scales!$B$6:$F$10, MATCH(_xlfn.NUMBERVALUE(raw!H5),scales!$A$6:$A$10,0), MATCH( _xlfn.XLOOKUP(raw!H$1,scales!$1:$1,scales!$2:$2), scales!$B$5:$F$5, 0 ) )) -> None or Few | I5: =IF(raw!I5="","",INDEX(scales!$B$6:$F$10, MATCH(_xlfn.NUMBERVALUE(raw!I5),scales!$A$6:$A$10,0), MATCH( _xlfn.XLOOKUP(raw!I$1,scales!$1:$1,scales!$2:$2), scales!$B$5:$F$5, 0 ) )) -> None or Few | ... BM5: =IF(raw!BM5="","",INDEX(scales!$B$6:$F$10, MATCH(_xlfn.NUMBERVALUE(raw!BM5),scales!$A$6:$A$10,0), MATCH( _xlfn.XLOOKUP(raw!BM$1,scales!$1:$1,scales!$2:$2), scales!$B$5:$F$5, 0 ) )) -> Some
A6: Zimbabwe | B6: =IF(raw!B6="","",INDEX(scales!$B$6:$F$10, MATCH(_xlfn.NUMBERVALUE(raw!B6),scales!$A$6:$A$10,0), MATCH( _xlfn.XLOOKUP(raw!B$1,scales!$1:$1,scales!$2:$2), scales!$B$5:$F$5, 0 ) )) -> Do not know | C6: =IF(raw!C6="","",INDEX(scales!$B$6:$F$10, MATCH(_xlfn.NUMBERVALUE(raw!C6),scales!$A$6:$A$10,0), MATCH( _xlfn.XLOOKUP(raw!C$1,scales!$1:$1,scales!$2:$2), scales!$B$5:$F$5, 0 ) )) -> Do not know | D6: =IF(raw!D6="","",INDEX(scales!$B$6:$F$10, MATCH(_xlfn.NUMBERVALUE(raw!D6),scales!$A$6:$A$10,0), MATCH( _xlfn.XLOOKUP(raw!D$1,scales!$1:$1,scales!$2:$2), scales!$B$5:$F$5, 0 ) )) -> Do not know | E6: =IF(raw!E6="","",INDEX(scales!$B$6:$F$10, MATCH(_xlfn.NUMBERVALUE(raw!E6),scales!$A$6:$A$10,0), MATCH( _xlfn.XLOOKUP(raw!E$1,scales!$1:$1,scales!$2:$2), scales!$B$5:$F$5, 0 ) )) -> Do not know | F6: =IF(raw!F6="","",INDEX(scales!$B$6:$F$10, MATCH(_xlfn.NUMBERVALUE(raw!F6),scales!$A$6:$A$10,0), MATCH( _xlfn.XLOOKUP(raw!F$1,scales!$1:$1,scales!$2:$2), scales!$B$5:$F$5, 0 ) )) -> Some | G6: =IF(raw!G6="","",INDEX(scales!$B$6:$F$10, MATCH(_xlfn.NUMBERVALUE(raw!G6),scales!$A$6:$A$10,0), MATCH( _xlfn.XLOOKUP(raw!G$1,scales!$1:$1,scales!$2:$2), scales!$B$5:$F$5, 0 ) )) -> Many | H6: =IF(raw!H6="","",INDEX(scales!$B$6:$F$10, MATCH(_xlfn.NUMBERVALUE(raw!H6),scales!$A$6:$A$10,0), MATCH( _xlfn.XLOOKUP(raw!H$1,scales!$1:$1,scales!$2:$2), scales!$B$5:$F$5, 0 ) )) -> Most or All | I6: =IF(raw!I6="","",INDEX(scales!$B$6:$F$10, MATCH(_xlfn.NUMBERVALUE(raw!I6),scales!$A$6:$A$10,0), MATCH( _xlfn.XLOOKUP(raw!I$1,scales!$1:$1,scales!$2:$2), scales!$B$5:$F$5, 0 ) )) -> None or Few | ... BM6: =IF(raw!BM6="","",INDEX(scales!$B$6:$F$10, MATCH(_xlfn.NUMBERVALUE(raw!BM6),scales!$A$6:$A$10,0), MATCH( _xlfn.XLOOKUP(raw!BM$1,scales!$1:$1,scales!$2:$2), scales!$B$5:$F$5, 0 ) )) -> A lot
A7: Spain | B7: =IF(raw!B7="","",INDEX(scales!$B$6:$F$10, MATCH(_xlfn.NUMBERVALUE(raw!B7),scales!$A$6:$A$10,0), MATCH( _xlfn.XLOOKUP(raw!B$1,scales!$1:$1,scales!$2:$2), scales!$B$5:$F$5, 0 ) )) -> Yes | C7: =IF(raw!C7="","",INDEX(scales!$B$6:$F$10, MATCH(_xlfn.NUMBERVALUE(raw!C7),scales!$A$6:$A$10,0), MATCH( _xlfn.XLOOKUP(raw!C$1,scales!$1:$1,scales!$2:$2), scales!$B$5:$F$5, 0 ) )) -> Yes | D7: =IF(raw!D7="","",INDEX(scales!$B$6:$F$10, MATCH(_xlfn.NUMBERVALUE(raw!D7),scales!$A$6:$A$10,0), MATCH( _xlfn.XLOOKUP(raw!D$1,scales!$1:$1,scales!$2:$2), scales!$B$5:$F$5, 0 ) )) -> Yes | E7: =IF(raw!E7="","",INDEX(scales!$B$6:$F$10, MATCH(_xlfn.NUMBERVALUE(raw!E7),scales!$A$6:$A$10,0), MATCH( _xlfn.XLOOKUP(raw!E$1,scales!$1:$1,scales!$2:$2), scales!$B$5:$F$5, 0 ) )) -> Yes | F7: =IF(raw!F7="","",INDEX(scales!$B$6:$F$10, MATCH(_xlfn.NUMBERVALUE(raw!F7),scales!$A$6:$A$10,0), MATCH( _xlfn.XLOOKUP(raw!F$1,scales!$1:$1,scales!$2:$2), scales!$B$5:$F$5, 0 ) )) -> Most or All | G7: =IF(raw!G7="","",INDEX(scales!$B$6:$F$10, MATCH(_xlfn.NUMBERVALUE(raw!G7),scales!$A$6:$A$10,0), MATCH( _xlfn.XLOOKUP(raw!G$1,scales!$1:$1,scales!$2:$2), scales!$B$5:$F$5, 0 ) )) -> Many | H7: =IF(raw!H7="","",INDEX(scales!$B$6:$F$10, MATCH(_xlfn.NUMBERVALUE(raw!H7),scales!$A$6:$A$10,0), MATCH( _xlfn.XLOOKUP(raw!H$1,scales!$1:$1,scales!$2:$2), scales!$B$5:$F$5, 0 ) )) -> Some | I7: =IF(raw!I7="","",INDEX(scales!$B$6:$F$10, MATCH(_xlfn.NUMBERVALUE(raw!I7),scales!$A$6:$A$10,0), MATCH( _xlfn.XLOOKUP(raw!I$1,scales!$1:$1,scales!$2:$2), scales!$B$5:$F$5, 0 ) )) -> None or Few | ... BM7: =IF(raw!BM7="","",INDEX(scales!$B$6:$F$10, MATCH(_xlfn.NUMBERVALUE(raw!BM7),scales!$A$6:$A$10,0), MATCH( _xlfn.XLOOKUP(raw!BM$1,scales!$1:$1,scales!$2:$2), scales!$B$5:$F$5, 0 ) )) -> Little
A8: Guatemala | B8: =IF(raw!B8="","",INDEX(scales!$B$6:$F$10, MATCH(_xlfn.NUMBERVALUE(raw!B8),scales!$A$6:$A$10,0), MATCH( _xlfn.XLOOKUP(raw!B$1,scales!$1:$1,scales!$2:$2), scales!$B$5:$F$5, 0 ) )) -> Yes | C8: =IF(raw!C8="","",INDEX(scales!$B$6:$F$10, MATCH(_xlfn.NUMBERVALUE(raw!C8),scales!$A$6:$A$10,0), MATCH( _xlfn.XLOOKUP(raw!C$1,scales!$1:$1,scales!$2:$2), scales!$B$5:$F$5, 0 ) )) -> Yes | D8: =IF(raw!D8="","",INDEX(scales!$B$6:$F$10, MATCH(_xlfn.NUMBERVALUE(raw!D8),scales!$A$6:$A$10,0), MATCH( _xlfn.XLOOKUP(raw!D$1,scales!$1:$1,scales!$2:$2), scales!$B$5:$F$5, 0 ) )) -> Yes | E8: =IF(raw!E8="","",INDEX(scales!$B$6:$F$10, MATCH(_xlfn.NUMBERVALUE(raw!E8),scales!$A$6:$A$10,0), MATCH( _xlfn.XLOOKUP(raw!E$1,scales!$1:$1,scales!$2:$2), scales!$B$5:$F$5, 0 ) )) -> Yes | F8: =IF(raw!F8="","",INDEX(scales!$B$6:$F$10, MATCH(_xlfn.NUMBERVALUE(raw!F8),scales!$A$6:$A$10,0), MATCH( _xlfn.XLOOKUP(raw!F$1,scales!$1:$1,scales!$2:$2), scales!$B$5:$F$5, 0 ) )) -> Some | G8: =IF(raw!G8="","",INDEX(scales!$B$6:$F$10, MATCH(_xlfn.NUMBERVALUE(raw!G8),scales!$A$6:$A$10,0), MATCH( _xlfn.XLOOKUP(raw!G$1,scales!$1:$1,scales!$2:$2), scales!$B$5:$F$5, 0 ) )) -> Some | H8: =IF(raw!H8="","",INDEX(scales!$B$6:$F$10, MATCH(_xlfn.NUMBERVALUE(raw!H8),scales!$A$6:$A$10,0), MATCH( _xlfn.XLOOKUP(raw!H$1,scales!$1:$1,scales!$2:$2), scales!$B$5:$F$5, 0 ) )) -> Many | I8: =IF(raw!I8="","",INDEX(scales!$B$6:$F$10, MATCH(_xlfn.NUMBERVALUE(raw!I8),scales!$A$6:$A$10,0), MATCH( _xlfn.XLOOKUP(raw!I$1,scales!$1:$1,scales!$2:$2), scales!$B$5:$F$5, 0 ) )) -> Most or All | ... BM8: =IF(raw!BM8="","",INDEX(scales!$B$6:$F$10, MATCH(_xlfn.NUMBERVALUE(raw!BM8),scales!$A$6:$A$10,0), MATCH( _xlfn.XLOOKUP(raw!BM$1,scales!$1:$1,scales!$2:$2), scales!$B$5:$F$5, 0 ) )) -> Little
A9: Colombia | B9: =IF(raw!B9="","",INDEX(scales!$B$6:$F$10, MATCH(_xlfn.NUMBERVALUE(raw!B9),scales!$A$6:$A$10,0), MATCH( _xlfn.XLOOKUP(raw!B$1,scales!$1:$1,scales!$2:$2), scales!$B$5:$F$5, 0 ) )) -> Yes | C9: =IF(raw!C9="","",INDEX(scales!$B$6:$F$10, MATCH(_xlfn.NUMBERVALUE(raw!C9),scales!$A$6:$A$10,0), MATCH( _xlfn.XLOOKUP(raw!C$1,scales!$1:$1,scales!$2:$2), scales!$B$5:$F$5, 0 ) )) -> No | D9: =IF(raw!D9="","",INDEX(scales!$B$6:$F$10, MATCH(_xlfn.NUMBERVALUE(raw!D9),scales!$A$6:$A$10,0), MATCH( _xlfn.XLOOKUP(raw!D$1,scales!$1:$1,scales!$2:$2), scales!$B$5:$F$5, 0 ) )) -> No | E9: =IF(raw!E9="","",INDEX(scales!$B$6:$F$10, MATCH(_xlfn.NUMBERVALUE(raw!E9),scales!$A$6:$A$10,0), MATCH( _xlfn.XLOOKUP(raw!E$1,scales!$1:$1,scales!$2:$2), scales!$B$5:$F$5, 0 ) )) -> Yes | F9: =IF(raw!F9="","",INDEX(scales!$B$6:$F$10, MATCH(_xlfn.NUMBERVALUE(raw!F9),scales!$A$6:$A$10,0), MATCH( _xlfn.XLOOKUP(raw!F$1,scales!$1:$1,scales!$2:$2), scales!$B$5:$F$5, 0 ) )) -> Some | G9: =IF(raw!G9="","",INDEX(scales!$B$6:$F$10, MATCH(_xlfn.NUMBERVALUE(raw!G9),scales!$A$6:$A$10,0), MATCH( _xlfn.XLOOKUP(raw!G$1,scales!$1:$1,scales!$2:$2), scales!$B$5:$F$5, 0 ) )) -> Many | H9: =IF(raw!H9="","",INDEX(scales!$B$6:$F$10, MATCH(_xlfn.NUMBERVALUE(raw!H9),scales!$A$6:$A$10,0), MATCH( _xlfn.XLOOKUP(raw!H$1,scales!$1:$1,scales!$2:$2), scales!$B$5:$F$5, 0 ) )) -> Some | I9: =IF(raw!I9="","",INDEX(scales!$B$6:$F$10, MATCH(_xlfn.NUMBERVALUE(raw!I9),scales!$A$6:$A$10,0), MATCH( _xlfn.XLOOKUP(raw!I$1,scales!$1:$1,scales!$2:$2), scales!$B$5:$F$5, 0 ) )) -> None or Few | ... BM9: =IF(raw!BM9="","",INDEX(scales!$B$6:$F$10, MATCH(_xlfn.NUMBERVALUE(raw!BM9),scales!$A$6:$A$10,0), MATCH( _xlfn.XLOOKUP(raw!BM$1,scales!$1:$1,scales!$2:$2), scales!$B$5:$F$5, 0 ) )) -> A lot
A10: Colombia | B10: =IF(raw!B10="","",INDEX(scales!$B$6:$F$10, MATCH(_xlfn.NUMBERVALUE(raw!B10),scales!$A$6:$A$10,0), MATCH( _xlfn.XLOOKUP(raw!B$1,scales!$1:$1,scales!$2:$2), scales!$B$5:$F$5, 0 ) )) -> Yes | C10: =IF(raw!C10="","",INDEX(scales!$B$6:$F$10, MATCH(_xlfn.NUMBERVALUE(raw!C10),scales!$A$6:$A$10,0), MATCH( _xlfn.XLOOKUP(raw!C$1,scales!$1:$1,scales!$2:$2), scales!$B$5:$F$5, 0 ) )) -> Yes | D10: =IF(raw!D10="","",INDEX(scales!$B$6:$F$10, MATCH(_xlfn.NUMBERVALUE(raw!D10),scales!$A$6:$A$10,0), MATCH( _xlfn.XLOOKUP(raw!D$1,scales!$1:$1,scales!$2:$2), scales!$B$5:$F$5, 0 ) )) -> Yes | E10: =IF(raw!E10="","",INDEX(scales!$B$6:$F$10, MATCH(_xlfn.NUMBERVALUE(raw!E10),scales!$A$6:$A$10,0), MATCH( _xlfn.XLOOKUP(raw!E$1,scales!$1:$1,scales!$2:$2), scales!$B$5:$F$5, 0 ) )) -> Yes | F10: =IF(raw!F10="","",INDEX(scales!$B$6:$F$10, MATCH(_xlfn.NUMBERVALUE(raw!F10),scales!$A$6:$A$10,0), MATCH( _xlfn.XLOOKUP(raw!F$1,scales!$1:$1,scales!$2:$2), scales!$B$5:$F$5, 0 ) )) -> Most or All | G10: =IF(raw!G10="","",INDEX(scales!$B$6:$F$10, MATCH(_xlfn.NUMBERVALUE(raw!G10),scales!$A$6:$A$10,0), MATCH( _xlfn.XLOOKUP(raw!G$1,scales!$1:$1,scales!$2:$2), scales!$B$5:$F$5, 0 ) )) -> Some | H10: =IF(raw!H10="","",INDEX(scales!$B$6:$F$10, MATCH(_xlfn.NUMBERVALUE(raw!H10),scales!$A$6:$A$10,0), MATCH( _xlfn.XLOOKUP(raw!H$1,scales!$1:$1,scales!$2:$2), scales!$B$5:$F$5, 0 ) )) -> None or Few | I10: =IF(raw!I10="","",INDEX(scales!$B$6:$F$10, MATCH(_xlfn.NUMBERVALUE(raw!I10),scales!$A$6:$A$10,0), MATCH( _xlfn.XLOOKUP(raw!I$1,scales!$1:$1,scales!$2:$2), scales!$B$5:$F$5, 0 ) )) -> Some | ... BM10: =IF(raw!BM10="","",INDEX(scales!$B$6:$F$10, MATCH(_xlfn.NUMBERVALUE(raw!BM10),scales!$A$6:$A$10,0), MATCH( _xlfn.XLOOKUP(raw!BM$1,scales!$1:$1,scales!$2:$2), scales!$B$5:$F$5, 0 ) )) -> A lot
A11: Spain | B11: =IF(raw!B11="","",INDEX(scales!$B$6:$F$10, MATCH(_xlfn.NUMBERVALUE(raw!B11),scales!$A$6:$A$10,0), MATCH( _xlfn.XLOOKUP(raw!B$1,scales!$1:$1,scales!$2:$2), scales!$B$5:$F$5, 0 ) )) -> Yes | C11: =IF(raw!C11="","",INDEX(scales!$B$6:$F$10, MATCH(_xlfn.NUMBERVALUE(raw!C11),scales!$A$6:$A$10,0), MATCH( _xlfn.XLOOKUP(raw!C$1,scales!$1:$1,scales!$2:$2), scales!$B$5:$F$5, 0 ) )) -> No | D11: =IF(raw!D11="","",INDEX(scales!$B$6:$F$10, MATCH(_xlfn.NUMBERVALUE(raw!D11),scales!$A$6:$A$10,0), MATCH( _xlfn.XLOOKUP(raw!D$1,scales!$1:$1,scales!$2:$2), scales!$B$5:$F$5, 0 ) )) -> Yes | E11: =IF(raw!E11="","",INDEX(scales!$B$6:$F$10, MATCH(_xlfn.NUMBERVALUE(raw!E11),scales!$A$6:$A$10,0), MATCH( _xlfn.XLOOKUP(raw!E$1,scales!$1:$1,scales!$2:$2), scales!$B$5:$F$5, 0 ) )) -> Yes | F11: =IF(raw!F11="","",INDEX(scales!$B$6:$F$10, MATCH(_xlfn.NUMBERVALUE(raw!F11),scales!$A$6:$A$10,0), MATCH( _xlfn.XLOOKUP(raw!F$1,scales!$1:$1,scales!$2:$2), scales!$B$5:$F$5, 0 ) )) -> Most or All | G11: =IF(raw!G11="","",INDEX(scales!$B$6:$F$10, MATCH(_xlfn.NUMBERVALUE(raw!G11),scales!$A$6:$A$10,0), MATCH( _xlfn.XLOOKUP(raw!G$1,scales!$1:$1,scales!$2:$2), scales!$B$5:$F$5, 0 ) )) -> None or Few | H11: =IF(raw!H11="","",INDEX(scales!$B$6:$F$10, MATCH(_xlfn.NUMBERVALUE(raw!H11),scales!$A$6:$A$10,0), MATCH( _xlfn.XLOOKUP(raw!H$1,scales!$1:$1,scales!$2:$2), scales!$B$5:$F$5, 0 ) )) -> None or Few | I11: =IF(raw!I11="","",INDEX(scales!$B$6:$F$10, MATCH(_xlfn.NUMBERVALUE(raw!I11),scales!$A$6:$A$10,0), MATCH( _xlfn.XLOOKUP(raw!I$1,scales!$1:$1,scales!$2:$2), scales!$B$5:$F$5, 0 ) )) -> Most or All | ... BM11: =IF(raw!BM11="","",INDEX(scales!$B$6:$F$10, MATCH(_xlfn.NUMBERVALUE(raw!BM11),scales!$A$6:$A$10,0), MATCH( _xlfn.XLOOKUP(raw!BM$1,scales!$1:$1,scales!$2:$2), scales!$B$5:$F$5, 0 ) )) -> Some
A12: Netherlands | B12: =IF(raw!B12="","",INDEX(scales!$B$6:$F$10, MATCH(_xlfn.NUMBERVALUE(raw!B12),scales!$A$6:$A$10,0), MATCH( _xlfn.XLOOKUP(raw!B$1,scales!$1:$1,scales!$2:$2), scales!$B$5:$F$5, 0 ) )) -> Yes | C12: =IF(raw!C12="","",INDEX(scales!$B$6:$F$10, MATCH(_xlfn.NUMBERVALUE(raw!C12),scales!$A$6:$A$10,0), MATCH( _xlfn.XLOOKUP(raw!C$1,scales!$1:$1,scales!$2:$2), scales!$B$5:$F$5, 0 ) )) -> Yes | D12: =IF(raw!D12="","",INDEX(scales!$B$6:$F$10, MATCH(_xlfn.NUMBERVALUE(raw!D12),scales!$A$6:$A$10,0), MATCH( _xlfn.XLOOKUP(raw!D$1,scales!$1:$1,scales!$2:$2), scales!$B$5:$F$5, 0 ) )) -> Yes | E12: =IF(raw!E12="","",INDEX(scales!$B$6:$F$10, MATCH(_xlfn.NUMBERVALUE(raw!E12),scales!$A$6:$A$10,0), MATCH( _xlfn.XLOOKUP(raw!E$1,scales!$1:$1,scales!$2:$2), scales!$B$5:$F$5, 0 ) )) -> Yes | F12: =IF(raw!F12="","",INDEX(scales!$B$6:$F$10, MATCH(_xlfn.NUMBERVALUE(raw!F12),scales!$A$6:$A$10,0), MATCH( _xlfn.XLOOKUP(raw!F$1,scales!$1:$1,scales!$2:$2), scales!$B$5:$F$5, 0 ) )) -> Most or All | G12: =IF(raw!G12="","",INDEX(scales!$B$6:$F$10, MATCH(_xlfn.NUMBERVALUE(raw!G12),scales!$A$6:$A$10,0), MATCH( _xlfn.XLOOKUP(raw!G$1,scales!$1:$1,scales!$2:$2), scales!$B$5:$F$5, 0 ) )) -> Some | H12: =IF(raw!H12="","",INDEX(scales!$B$6:$F$10, MATCH(_xlfn.NUMBERVALUE(raw!H12),scales!$A$6:$A$10,0), MATCH( _xlfn.XLOOKUP(raw!H$1,scales!$1:$1,scales!$2:$2), scales!$B$5:$F$5, 0 ) )) -> Some | I12: =IF(raw!I12="","",INDEX(scales!$B$6:$F$10, MATCH(_xlfn.NUMBERVALUE(raw!I12),scales!$A$6:$A$10,0), MATCH( _xlfn.XLOOKUP(raw!I$1,scales!$1:$1,scales!$2:$2), scales!$B$5:$F$5, 0 ) )) -> Most or All | ... BM12: =IF(raw!BM12="","",INDEX(scales!$B$6:$F$10, MATCH(_xlfn.NUMBERVALUE(raw!BM12),scales!$A$6:$A$10,0), MATCH( _xlfn.XLOOKUP(raw!BM$1,scales!$1:$1,scales!$2:$2), scales!$B$5:$F$5, 0 ) )) -> Some
A13: Colombia | B13: =IF(raw!B13="","",INDEX(scales!$B$6:$F$10, MATCH(_xlfn.NUMBERVALUE(raw!B13),scales!$A$6:$A$10,0), MATCH( _xlfn.XLOOKUP(raw!B$1,scales!$1:$1,scales!$2:$2), scales!$B$5:$F$5, 0 ) )) -> Yes | C13: =IF(raw!C13="","",INDEX(scales!$B$6:$F$10, MATCH(_xlfn.NUMBERVALUE(raw!C13),scales!$A$6:$A$10,0), MATCH( _xlfn.XLOOKUP(raw!C$1,scales!$1:$1,scales!$2:$2), scales!$B$5:$F$5, 0 ) )) -> Yes | D13: =IF(raw!D13="","",INDEX(scales!$B$6:$F$10, MATCH(_xlfn.NUMBERVALUE(raw!D13),scales!$A$6:$A$10,0), MATCH( _xlfn.XLOOKUP(raw!D$1,scales!$1:$1,scales!$2:$2), scales!$B$5:$F$5, 0 ) )) -> No | E13: =IF(raw!E13="","",INDEX(scales!$B$6:$F$10, MATCH(_xlfn.NUMBERVALUE(raw!E13),scales!$A$6:$A$10,0), MATCH( _xlfn.XLOOKUP(raw!E$1,scales!$1:$1,scales!$2:$2), scales!$B$5:$F$5, 0 ) )) -> Yes | F13: =IF(raw!F13="","",INDEX(scales!$B$6:$F$10, MATCH(_xlfn.NUMBERVALUE(raw!F13),scales!$A$6:$A$10,0), MATCH( _xlfn.XLOOKUP(raw!F$1,scales!$1:$1,scales!$2:$2), scales!$B$5:$F$5, 0 ) )) -> Many | G13: =IF(raw!G13="","",INDEX(scales!$B$6:$F$10, MATCH(_xlfn.NUMBERVALUE(raw!G13),scales!$A$6:$A$10,0), MATCH( _xlfn.XLOOKUP(raw!G$1,scales!$1:$1,scales!$2:$2), scales!$B$5:$F$5, 0 ) )) -> Many | H13: =IF(raw!H13="","",INDEX(scales!$B$6:$F$10, MATCH(_xlfn.NUMBERVALUE(raw!H13),scales!$A$6:$A$10,0), MATCH( _xlfn.XLOOKUP(raw!H$1,scales!$1:$1,scales!$2:$2), scales!$B$5:$F$5, 0 ) )) -> Many | I13: =IF(raw!I13="","",INDEX(scales!$B$6:$F$10, MATCH(_xlfn.NUMBERVALUE(raw!I13),scales!$A$6:$A$10,0), MATCH( _xlfn.XLOOKUP(raw!I$1,scales!$1:$1,scales!$2:$2), scales!$B$5:$F$5, 0 ) )) -> Many | ... BM13: =IF(raw!BM13="","",INDEX(scales!$B$6:$F$10, MATCH(_xlfn.NUMBERVALUE(raw!BM13),scales!$A$6:$A$10,0), MATCH( _xlfn.XLOOKUP(raw!BM$1,scales!$1:$1,scales!$2:$2), scales!$B$5:$F$5, 0 ) )) -> Little
... A49: United States | B49: =IF(raw!B49="","",INDEX(scales!$B$6:$F$10, MATCH(_xlfn.NUMBERVALUE(raw!B49),scales!$A$6:$A$10,0), MATCH( _xlfn.XLOOKUP(raw!B$1,scales!$1:$1,scales!$2:$2), scales!$B$5:$F$5, 0 ) )) -> Yes | C49: =IF(raw!C49="","",INDEX(scales!$B$6:$F$10, MATCH(_xlfn.NUMBERVALUE(raw!C49),scales!$A$6:$A$10,0), MATCH( _xlfn.XLOOKUP(raw!C$1,scales!$1:$1,scales!$2:$2), scales!$B$5:$F$5, 0 ) )) -> Yes | D49: =IF(raw!D49="","",INDEX(scales!$B$6:$F$10, MATCH(_xlfn.NUMBERVALUE(raw!D49),scales!$A$6:$A$10,0), MATCH( _xlfn.XLOOKUP(raw!D$1,scales!$1:$1,scales!$2:$2), scales!$B$5:$F$5, 0 ) )) -> Yes | E49: =IF(raw!E49="","",INDEX(scales!$B$6:$F$10, MATCH(_xlfn.NUMBERVALUE(raw!E49),scales!$A$6:$A$10,0), MATCH( _xlfn.XLOOKUP(raw!E$1,scales!$1:$1,scales!$2:$2), scales!$B$5:$F$5, 0 ) )) -> Yes | F49: =IF(raw!F49="","",INDEX(scales!$B$6:$F$10, MATCH(_xlfn.NUMBERVALUE(raw!F49),scales!$A$6:$A$10,0), MATCH( _xlfn.XLOOKUP(raw!F$1,scales!$1:$1,scales!$2:$2), scales!$B$5:$F$5, 0 ) )) -> Some | G49: =IF(raw!G49="","",INDEX(scales!$B$6:$F$10, MATCH(_xlfn.NUMBERVALUE(raw!G49),scales!$A$6:$A$10,0), MATCH( _xlfn.XLOOKUP(raw!G$1,scales!$1:$1,scales!$2:$2), scales!$B$5:$F$5, 0 ) )) -> Many | H49: =IF(raw!H49="","",INDEX(scales!$B$6:$F$10, MATCH(_xlfn.NUMBERVALUE(raw!H49),scales!$A$6:$A$10,0), MATCH( _xlfn.XLOOKUP(raw!H$1,scales!$1:$1,scales!$2:$2), scales!$B$5:$F$5, 0 ) )) -> Many | I49: =IF(raw!I49="","",INDEX(scales!$B$6:$F$10, MATCH(_xlfn.NUMBERVALUE(raw!I49),scales!$A$6:$A$10,0), MATCH( _xlfn.XLOOKUP(raw!I$1,scales!$1:$1,scales!$2:$2), scales!$B$5:$F$5, 0 ) )) -> Most or All | ... BM49: =IF(raw!BM49="","",INDEX(scales!$B$6:$F$10, MATCH(_xlfn.NUMBERVALUE(raw!BM49),scales!$A$6:$A$10,0), MATCH( _xlfn.XLOOKUP(raw!BM$1,scales!$1:$1,scales!$2:$2), scales!$B$5:$F$5, 0 ) )) -> Some
